/*
Write a C# program to demonstrate exception handling using try, catch and finally block.
*/

/*
class Program30{
    static void Main() {
        try {
            Console.WriteLine("Enter a number: ");
            int number = int.Parse(Console.ReadLine());

            Console.WriteLine("Enter a divisor: ");
            int divisor = int.Parse(Console.ReadLine());

            int result = number/ divisor;

            Console.WriteLine($"The result of {number} divide by {divisor} is: {result}");
        }
        catch(Exception ex){
            Console.WriteLine("Error: Invalid input please enter a valid number.");
            Console.WriteLine($"Details: {ex.Message}");
        }
        finally{
           Console.WriteLine("Code ends here...");
        }
    }
}
*/